Workbook

Sheet Dashboard
A1: Sales Dashboard 2025 | لوحة متابعة المبيعات 2025
A3: Total Sales (EGP) | D3: Total Orders | G3: Avg Order Value | J3: Best Month (Sales)
A4: =Monthly_Summary!D16 -> 13440426 | D4: =Monthly_Summary!C16 -> 7995 | G4: =Monthly_Summary!E16 -> 1681.104 | J4: =INDEX(Monthly_Summary!B4:B15, MATCH(MAX(Monthly_Summary!D4:D15), Monthly_Summary!D4:D15, 0)) -> فبراير
J6: =MAX(Monthly_Summary!D4:D15) -> 1567533.5

Sheet Monthly_Summary
A1: ملخص المبيعات 2025 | Sales Summary 2025
A3: MonthNo | B3: Month (AR) | C3: Orders | D3: Sales | E3: Avg Order | F3: MoM Sales % | G3: MoM Orders % | H3: Sales Share %
A4: 1 | B4: يناير | C4: =COUNTIF(Data_2025!$C:$C,A4) -> 394 | D4: =SUMIF(Data_2025!$C:$C,A4,Data_2025!$T:$T) -> 1033605 | E4: =IF(C4=0,"",D4/C4) -> 2623.3629 | H4: =IF($D$16=0,"",D4/$D$16) -> 0.076902694
A5: 2 | B5: فبراير | C5: =COUNTIF(Data_2025!$C:$C,A5) -> 826 | D5: =SUMIF(Data_2025!$C:$C,A5,Data_2025!$T:$T) -> 1567533.5 | E5: =IF(C5=0,"",D5/C5) -> 1897.7403 | F5: =IF(D4=0,"",D5/D4-1) -> 0.51656919 | G5: =IF(C4=0,"",C5/C4-1) -> 1.0964467 | H5: =IF($D$16=0,"",D5/$D$16) -> 0.11662826
A6: 3 | B6: مارس | C6: =COUNTIF(Data_2025!$C:$C,A6) -> 488 | D6: =SUMIF(Data_2025!$C:$C,A6,Data_2025!$T:$T) -> 927916 | E6: =IF(C6=0,"",D6/C6) -> 1901.4672 | F6: =IF(D5=0,"",D6/D5-1) -> -0.40804072 | G6: =IF(C5=0,"",C6/C5-1) -> -0.40920097 | H6: =IF($D$16=0,"",D6/$D$16) -> 0.069039178
A7: 4 | B7: أبريل | C7: =COUNTIF(Data_2025!$C:$C,A7) -> 486 | D7: =SUMIF(Data_2025!$C:$C,A7,Data_2025!$T:$T) -> 823230 | E7: =IF(C7=0,"",D7/C7) -> 1693.8889 | F7: =IF(D6=0,"",D7/D6-1) -> -0.1128184 | G7: =IF(C6=0,"",C7/C6-1) -> -0.0040983607 | H7: =IF($D$16=0,"",D7/$D$16) -> 0.061250288
A8: 5 | B8: مايو | C8: =COUNTIF(Data_2025!$C:$C,A8) -> 639 | D8: =SUMIF(Data_2025!$C:$C,A8,Data_2025!$T:$T) -> 1196154 | E8: =IF(C8=0,"",D8/C8) -> 1871.9155 | F8: =IF(D7=0,"",D8/D7-1) -> 0.45300098 | G8: =IF(C7=0,"",C8/C7-1) -> 0.31481481 | H8: =IF($D$16=0,"",D8/$D$16) -> 0.088996729
A9: 6 | B9: يونيو | C9: =COUNTIF(Data_2025!$C:$C,A9) -> 311 | D9: =SUMIF(Data_2025!$C:$C,A9,Data_2025!$T:$T) -> 636635 | E9: =IF(C9=0,"",D9/C9) -> 2047.0579 | F9: =IF(D8=0,"",D9/D8-1) -> -0.46776502 | G9: =IF(C8=0,"",C9/C8-1) -> -0.51330203 | H9: =IF($D$16=0,"",D9/$D$16) -> 0.047367172
A10: 7 | B10: يوليو | C10: =COUNTIF(Data_2025!$C:$C,A10) -> 766 | D10: =SUMIF(Data_2025!$C:$C,A10,Data_2025!$T:$T) -> 1223935 | E10: =IF(C10=0,"",D10/C10) -> 1597.8264 | F10: =IF(D9=0,"",D10/D9-1) -> 0.92250662 | G10: =IF(C9=0,"",C10/C9-1) -> 1.4630225 | H10: =IF($D$16=0,"",D10/$D$16) -> 0.091063702
A11: 8 | B11: أغسطس | C11: =COUNTIF(Data_2025!$C:$C,A11) -> 1115 | D11: =SUMIF(Data_2025!$C:$C,A11,Data_2025!$T:$T) -> 1491726 | E11: =IF(C11=0,"",D11/C11) -> 1337.8709 | F11: =IF(D10=0,"",D11/D10-1) -> 0.21879512 | G11: =IF(C10=0,"",C11/C10-1) -> 0.45561358 | H11: =IF($D$16=0,"",D11/$D$16) -> 0.110988
A12: 9 | B12: سبتمبر | C12: =COUNTIF(Data_2025!$C:$C,A12) -> 875 | D12: =SUMIF(Data_2025!$C:$C,A12,Data_2025!$T:$T) -> 1260150 | E12: =IF(C12=0,"",D12/C12) -> 1440.1714 | F12: =IF(D11=0,"",D12/D11-1) -> -0.15524031 | G12: =IF(C11=0,"",C12/C11-1) -> -0.21524664 | H12: =IF($D$16=0,"",D12/$D$16) -> 0.093758185
A13: 10 | B13: أكتوبر | C13: =COUNTIF(Data_2025!$C:$C,A13) -> 717 | D13: =SUMIF(Data_2025!$C:$C,A13,Data_2025!$T:$T) -> 1023910 | E13: =IF(C13=0,"",D13/C13) -> 1428.0474 | F13: =IF(D12=0,"",D13/D12-1) -> -0.18746975 | G13: =IF(C12=0,"",C13/C12-1) -> -0.18057143 | H13: =IF($D$16=0,"",D13/$D$16) -> 0.076181362
A14: 11 | B14: نوفمبر | C14: =COUNTIF(Data_2025!$C:$C,A14) -> 663 | D14: =SUMIF(Data_2025!$C:$C,A14,Data_2025!$T:$T) -> 1022121 | E14: =IF(C14=0,"",D14/C14) -> 1541.6606 | F14: =IF(D13=0,"",D14/D13-1) -> -0.0017472239 | G14: =IF(C13=0,"",C14/C13-1) -> -0.075313808 | H14: =IF($D$16=0,"",D14/$D$16) -> 0.076048256
A15: 12 | B15: ديسمبر | C15: =COUNTIF(Data_2025!$C:$C,A15) -> 715 | D15: =SUMIF(Data_2025!$C:$C,A15,Data_2025!$T:$T) -> 1233511 | E15: =IF(C15=0,"",D15/C15) -> 1725.1902 | F15: =IF(D14=0,"",D15/D14-1) -> 0.20681504 | G15: =IF(C14=0,"",C15/C14-1) -> 0.078431373 | H15: =IF($D$16=0,"",D15/$D$16) -> 0.09177618
B16: TOTAL | C16: =SUM(C4:C15) -> 7995 | D16: =SUM(D4:D15) -> 13440426 | E16: =IF(C16=0,"",D16/C16) -> 1681.104 | H16: =1 -> 1

Sheet Geo
A1: المبيعات حسب المحافظة | Sales by Governorate
B2: Total Sales | C2: =SUM(Data_2025!$T:$T) -> 13440426 | E2: Top 10
A3: Governorate | B3: Orders | C3: Sales | D3: Avg Order | E3: Sales Share % | F3: Rank | H3: Rank | I3: Governorate | J3: Sales | K3: Orders
A4: القاهرة | B4: =COUNTIF(Data_2025!$M:$M,A4) -> 3202 | C4: =SUMIF(Data_2025!$M:$M,A4,Data_2025!$T:$T) -> 5041772 | D4: =IF(B4=0,"",C4/B4) -> 1574.5696 | E4: =IF($C$2=0,"",C4/$C$2) -> 0.37511994 | F4: =_xludf.RANK.EQ(C4,$C$4:$C$45,0) -> #NAME? | H4: 1 | I4: =INDEX($A$4:$A$45,MATCH(H4,$F$4:$F$45,0)) -> #N/A | J4: =LARGE($C$4:$C$45,H4) -> 5041772 | K4: =INDEX($B$4:$B$45,MATCH(H4,$F$4:$F$45,0)) -> #N/A
A5: الجيزة | B5: =COUNTIF(Data_2025!$M:$M,A5) -> 1249 | C5: =SUMIF(Data_2025!$M:$M,A5,Data_2025!$T:$T) -> 1847942 | D5: =IF(B5=0,"",C5/B5) -> 1479.5372 | E5: =IF($C$2=0,"",C5/$C$2) -> 0.13749132 | F5: =_xludf.RANK.EQ(C5,$C$4:$C$45,0) -> #NAME? | H5: 2 | I5: =INDEX($A$4:$A$45,MATCH(H5,$F$4:$F$45,0)) -> #N/A | J5: =LARGE($C$4:$C$45,H5) -> 1847942 | K5: =INDEX($B$4:$B$45,MATCH(H5,$F$4:$F$45,0)) -> #N/A
A6: الغربية | B6: =COUNTIF(Data_2025!$M:$M,A6) -> 1073 | C6: =SUMIF(Data_2025!$M:$M,A6,Data_2025!$T:$T) -> 1575427 | D6: =IF(B6=0,"",C6/B6) -> 1468.2451 | E6: =IF($C$2=0,"",C6/$C$2) -> 0.11721555 | F6: =_xludf.RANK.EQ(C6,$C$4:$C$45,0) -> #NAME? | H6: 3 | I6: =INDEX($A$4:$A$45,MATCH(H6,$F$4:$F$45,0)) -> #N/A | J6: =LARGE($C$4:$C$45,H6) -> 1575427 | K6: =INDEX($B$4:$B$45,MATCH(H6,$F$4:$F$45,0)) -> #N/A
A7: الإسكندرية | B7: =COUNTIF(Data_2025!$M:$M,A7) -> 380 | C7: =SUMIF(Data_2025!$M:$M,A7,Data_2025!$T:$T) -> 1253208 | D7: =IF(B7=0,"",C7/B7) -> 3297.9158 | E7: =IF($C$2=0,"",C7/$C$2) -> 0.093241684 | F7: =_xludf.RANK.EQ(C7,$C$4:$C$45,0) -> #NAME? | H7: 4 | I7: =INDEX($A$4:$A$45,MATCH(H7,$F$4:$F$45,0)) -> #N/A | J7: =LARGE($C$4:$C$45,H7) -> 1253208 | K7: =INDEX($B$4:$B$45,MATCH(H7,$F$4:$F$45,0)) -> #N/A
A8: الدقهلية | B8: =COUNTIF(Data_2025!$M:$M,A8) -> 477 | C8: =SUMIF(Data_2025!$M:$M,A8,Data_2025!$T:$T) -> 839966 | D8: =IF(B8=0,"",C8/B8) -> 1760.935 | E8: =IF($C$2=0,"",C8/$C$2) -> 0.062495487 | F8: =_xludf.RANK.EQ(C8,$C$4:$C$45,0) -> #NAME? | H8: 5 | I8: =INDEX($A$4:$A$45,MATCH(H8,$F$4:$F$45,0)) -> #N/A | J8: =LARGE($C$4:$C$45,H8) -> 839966 | K8: =INDEX($B$4:$B$45,MATCH(H8,$F$4:$F$45,0)) -> #N/A
A9: الشرقية | B9: =COUNTIF(Data_2025!$M:$M,A9) -> 406 | C9: =SUMIF(Data_2025!$M:$M,A9,Data_2025!$T:$T) -> 663013.5 | D9: =IF(B9=0,"",C9/B9) -> 1633.0382 | E9: =IF($C$2=0,"",C9/$C$2) -> 0.049329796 | F9: =_xludf.RANK.EQ(C9,$C$4:$C$45,0) -> #NAME? | H9: 6 | I9: =INDEX($A$4:$A$45,MATCH(H9,$F$4:$F$45,0)) -> #N/A | J9: =LARGE($C$4:$C$45,H9) -> 663013.5 | K9: =INDEX($B$4:$B$45,MATCH(H9,$F$4:$F$45,0)) -> #N/A
A10: القليوبية | B10: =COUNTIF(Data_2025!$M:$M,A10) -> 406 | C10: =SUMIF(Data_2025!$M:$M,A10,Data_2025!$T:$T) -> 632564 | D10: =IF(B10=0,"",C10/B10) -> 1558.0394 | E10: =IF($C$2=0,"",C10/$C$2) -> 0.04706428 | F10: =_xludf.RANK.EQ(C10,$C$4:$C$45,0) -> #NAME? | H10: 7 | I10: =INDEX($A$4:$A$45,MATCH(H10,$F$4:$F$45,0)) -> #N/A | J10: =LARGE($C$4:$C$45,H10) -> 632564 | K10: =INDEX($B$4:$B$45,MATCH(H10,$F$4:$F$45,0)) -> #N/A
A11: المنوفية | B11: =COUNTIF(Data_2025!$M:$M,A11) -> 262 | C11: =SUMIF(Data_2025!$M:$M,A11,Data_2025!$T:$T) -> 447913 | D11: =IF(B11=0,"",C11/B11) -> 1709.5916 | E11: =IF($C$2=0,"",C11/$C$2) -> 0.033325803 | F11: =_xludf.RANK.EQ(C11,$C$4:$C$45,0) -> #NAME? | H11: 8 | I11: =INDEX($A$4:$A$45,MATCH(H11,$F$4:$F$45,0)) -> #N/A | J11: =LARGE($C$4:$C$45,H11) -> 447913 | K11: =INDEX($B$4:$B$45,MATCH(H11,$F$4:$F$45,0)) -> #N/A
A12: البحيرة | B12: =COUNTIF(Data_2025!$M:$M,A12) -> 181 | C12: =SUMIF(Data_2025!$M:$M,A12,Data_2025!$T:$T) -> 269096 | D12: =IF(B12=0,"",C12/B12) -> 1486.7182 | E12: =IF($C$2=0,"",C12/$C$2) -> 0.020021388 | F12: =_xludf.RANK.EQ(C12,$C$4:$C$45,0) -> #NAME? | H12: 9 | I12: =INDEX($A$4:$A$45,MATCH(H12,$F$4:$F$45,0)) -> #N/A | J12: =LARGE($C$4:$C$45,H12) -> 269096 | K12: =INDEX($B$4:$B$45,MATCH(H12,$F$4:$F$45,0)) -> #N/A
A13: كفر الشيخ | B13: =COUNTIF(Data_2025!$M:$M,A13) -> 142 | C13: =SUMIF(Data_2025!$M:$M,A13,Data_2025!$T:$T) -> 248030 | D13: =IF(B13=0,"",C13/B13) -> 1746.6901 | E13: =IF($C$2=0,"",C13/$C$2) -> 0.018454027 | F13: =_xludf.RANK.EQ(C13,$C$4:$C$45,0) -> #NAME? | H13: 10 | I13: =INDEX($A$4:$A$45,MATCH(H13,$F$4:$F$45,0)) -> #N/A | J13: =LARGE($C$4:$C$45,H13) -> 248030 | K13: =INDEX($B$4:$B$45,MATCH(H13,$F$4:$F$45,0)) -> #N/A
A14: الغردقه | B14: =COUNTIF(Data_2025!$M:$M,A14) -> 4 | C14: =SUMIF(Data_2025!$M:$M,A14,Data_2025!$T:$T) -> 196275 | D14: =IF(B14=0,"",C14/B14) -> 49068.75 | E14: =IF($C$2=0,"",C14/$C$2) -> 0.014603331 | F14: =_xludf.RANK.EQ(C14,$C$4:$C$45,0) -> #NAME?
A15: دمياط | B15: =COUNTIF(Data_2025!$M:$M,A15) -> 47 | C15: =SUMIF(Data_2025!$M:$M,A15,Data_2025!$T:$T) -> 87225 | D15: =IF(B15=0,"",C15/B15) -> 1855.8511 | E15: =IF($C$2=0,"",C15/$C$2) -> 0.0064897494 | F15: =_xludf.RANK.EQ(C15,$C$4:$C$45,0) -> #NAME?
A16: السويس | B16: =COUNTIF(Data_2025!$M:$M,A16) -> 34 | C16: =SUMIF(Data_2025!$M:$M,A16,Data_2025!$T:$T) -> 63225 | D16: =IF(B16=0,"",C16/B16) -> 1859.5588 | E16: =IF($C$2=0,"",C16/$C$2) -> 0.0047040918 | F16: =_xludf.RANK.EQ(C16,$C$4:$C$45,0) -> #NAME?
A17: الإسماعيلية | B17: =COUNTIF(Data_2025!$M:$M,A17) -> 27 | C17: =SUMIF(Data_2025!$M:$M,A17,Data_2025!$T:$T) -> 50145 | D17: =IF(B17=0,"",C17/B17) -> 1857.2222 | E17: =IF($C$2=0,"",C17/$C$2) -> 0.0037309084 | F17: =_xludf.RANK.EQ(C17,$C$4:$C$45,0) -> #NAME?
A18: الفيوم | B18: =COUNTIF(Data_2025!$M:$M,A18) -> 3 | C18: =SUMIF(Data_2025!$M:$M,A18,Data_2025!$T:$T) -> 41290 | D18: =IF(B18=0,"",C18/B18) -> 13763.333 | E18: =IF($C$2=0,"",C18/$C$2) -> 0.0030720751 | F18: =_xludf.RANK.EQ(C18,$C$4:$C$45,0) -> #NAME?
A19: الاسماعيليه | B19: =COUNTIF(Data_2025!$M:$M,A19) -> 25 | C19: =SUMIF(Data_2025!$M:$M,A19,Data_2025!$T:$T) -> 34467 | D19: =IF(B19=0,"",C19/B19) -> 1378.68 | E19: =IF($C$2=0,"",C19/$C$2) -> 0.0025644275 | F19: =_xludf.RANK.EQ(C19,$C$4:$C$45,0) -> #NAME?
A20: بورسعيد | B20: =COUNTIF(Data_2025!$M:$M,A20) -> 14 | C20: =SUMIF(Data_2025!$M:$M,A20,Data_2025!$T:$T) -> 27674 | D20: =IF(B20=0,"",C20/B20) -> 1976.7143 | E20: =IF($C$2=0,"",C20/$C$2) -> 0.002059012 | F20: =_xludf.RANK.EQ(C20,$C$4:$C$45,0) -> #NAME?
A21: المنصوره | B21: =COUNTIF(Data_2025!$M:$M,A21) -> 20 | C21: =SUMIF(Data_2025!$M:$M,A21,Data_2025!$T:$T) -> 25680 | D21: =IF(B21=0,"",C21/B21) -> 1284 | E21: =IF($C$2=0,"",C21/$C$2) -> 0.0019106537 | F21: =_xludf.RANK.EQ(C21,$C$4:$C$45,0) -> #NAME?
A22: دمياط الجديدة | B22: =COUNTIF(Data_2025!$M:$M,A22) -> 4 | C22: =SUMIF(Data_2025!$M:$M,A22,Data_2025!$T:$T) -> 15200 | D22: =IF(B22=0,"",C22/B22) -> 3800 | E22: =IF($C$2=0,"",C22/$C$2) -> 0.0011309165 | F22: =_xludf.RANK.EQ(C22,$C$4:$C$45,0) -> #NAME?
A23: المنصورة | B23: =COUNTIF(Data_2025!$M:$M,A23) -> 4 | C23: =SUMIF(Data_2025!$M:$M,A23,Data_2025!$T:$T) -> 13550 | D23: =IF(B23=0,"",C23/B23) -> 3387.5 | E23: =IF($C$2=0,"",C23/$C$2) -> 0.0010081525 | F23: =_xludf.RANK.EQ(C23,$C$4:$C$45,0) -> #NAME?
A24: الاسماعيله | B24: =COUNTIF(Data_2025!$M:$M,A24) -> 8 | C24: =SUMIF(Data_2025!$M:$M,A24,Data_2025!$T:$T) -> 12350 | D24: =IF(B24=0,"",C24/B24) -> 1543.75 | E24: =IF($C$2=0,"",C24/$C$2) -> 0.00091886965 | F24: =_xludf.RANK.EQ(C24,$C$4:$C$45,0) -> #NAME?
A25: دمياط القديمه | B25: =COUNTIF(Data_2025!$M:$M,A25) -> 2 | C25: =SUMIF(Data_2025!$M:$M,A25,Data_2025!$T:$T) -> 7340 | D25: =IF(B25=0,"",C25/B25) -> 3670 | E25: =IF($C$2=0,"",C25/$C$2) -> 0.00054611362 | F25: =_xludf.RANK.EQ(C25,$C$4:$C$45,0) -> #NAME?
... A45: الاسماعليه | B45: =COUNTIF(Data_2025!$M:$M,A45) -> 1 | C45: =SUMIF(Data_2025!$M:$M,A45,Data_2025!$T:$T) -> 900 | D45: =IF(B45=0,"",C45/B45) -> 900 | E45: =IF($C$2=0,"",C45/$C$2) -> 6.6962161e-05 | F45: =_xludf.RANK.EQ(C45,$C$4:$C$45,0) -> #NAME?

Sheet Channels
A1: القنوات والعمليات | Channels & Operations
B2: Total Sales | C2: =SUM(Data_2025!$T:$T) -> 13440426
A3: مصدر العميل (Normalized) | Source
A4: Category | B4: Orders | C4: Sales | D4: Avg Order | E4: Sales Share % | F4: Rank | H4: Rank | I4: مصدر العميل (Normalized) | J4: Sales
A5: مكالمة / واتساب | B5: =COUNTIF(Data_2025!$I:$I,A5) -> 3957 | C5: =SUMIF(Data_2025!$I:$I,A5,Data_2025!$T:$T) -> 7839848.5 | D5: =IF(B5=0,"",C5/B5) -> 1981.2607 | E5: =IF($C$2=0,"",C5/$C$2) -> 0.58330355 | F5: =_xludf.RANK.EQ(C5,$C$5:$C$21,0) -> #NAME? | H5: 1 | I5: =INDEX($A$5:$A$21,MATCH(H5,$F$5:$F$21,0)) -> #N/A | J5: =LARGE($C$5:$C$21,H5) -> 7839848.5
A6: حملات فيسبوك | B6: =COUNTIF(Data_2025!$I:$I,A6) -> 2121 | C6: =SUMIF(Data_2025!$I:$I,A6,Data_2025!$T:$T) -> 2628573 | D6: =IF(B6=0,"",C6/B6) -> 1239.3083 | E6: =IF($C$2=0,"",C6/$C$2) -> 0.19557214 | F6: =_xludf.RANK.EQ(C6,$C$5:$C$21,0) -> #NAME? | H6: 2 | I6: =INDEX($A$5:$A$21,MATCH(H6,$F$5:$F$21,0)) -> #N/A | J6: =LARGE($C$5:$C$21,H6) -> 2628573
A7: فيسبوك | B7: =COUNTIF(Data_2025!$I:$I,A7) -> 1585 | C7: =SUMIF(Data_2025!$I:$I,A7,Data_2025!$T:$T) -> 2442068 | D7: =IF(B7=0,"",C7/B7) -> 1540.7369 | E7: =IF($C$2=0,"",C7/$C$2) -> 0.18169572 | F7: =_xludf.RANK.EQ(C7,$C$5:$C$21,0) -> #NAME? | H7: 3 | I7: =INDEX($A$5:$A$21,MATCH(H7,$F$5:$F$21,0)) -> #N/A | J7: =LARGE($C$5:$C$21,H7) -> 2442068
A8: حملات واتس | B8: =COUNTIF(Data_2025!$I:$I,A8) -> 251 | C8: =SUMIF(Data_2025!$I:$I,A8,Data_2025!$T:$T) -> 362422 | D8: =IF(B8=0,"",C8/B8) -> 1443.9124 | E8: =IF($C$2=0,"",C8/$C$2) -> 0.026965067 | F8: =_xludf.RANK.EQ(C8,$C$5:$C$21,0) -> #NAME? | H8: 4 | I8: =INDEX($A$5:$A$21,MATCH(H8,$F$5:$F$21,0)) -> #N/A | J8: =LARGE($C$5:$C$21,H8) -> 362422
A9: تيك توك | B9: =COUNTIF(Data_2025!$I:$I,A9) -> 27 | C9: =SUMIF(Data_2025!$I:$I,A9,Data_2025!$T:$T) -> 55655 | D9: =IF(B9=0,"",C9/B9) -> 2061.2963 | E9: =IF($C$2=0,"",C9/$C$2) -> 0.0041408656 | F9: =_xludf.RANK.EQ(C9,$C$5:$C$21,0) -> #NAME? | H9: 5 | I9: =INDEX($A$5:$A$21,MATCH(H9,$F$5:$F$21,0)) -> #N/A | J9: =LARGE($C$5:$C$21,H9) -> 55655
A10: تواصل | B10: =COUNTIF(Data_2025!$I:$I,A10) -> 1 | C10: =SUMIF(Data_2025!$I:$I,A10,Data_2025!$T:$T) -> 31675 | D10: =IF(B10=0,"",C10/B10) -> 31675 | E10: =IF($C$2=0,"",C10/$C$2) -> 0.002356696 | F10: =_xludf.RANK.EQ(C10,$C$5:$C$21,0) -> #NAME?
A11: ويب سايت | B11: =COUNTIF(Data_2025!$I:$I,A11) -> 16 | C11: =SUMIF(Data_2025!$I:$I,A11,Data_2025!$T:$T) -> 28330 | D11: =IF(B11=0,"",C11/B11) -> 1770.625 | E11: =IF($C$2=0,"",C11/$C$2) -> 0.00210782 | F11: =_xludf.RANK.EQ(C11,$C$5:$C$21,0) -> #NAME?
A12: اعلان | B12: =COUNTIF(Data_2025!$I:$I,A12) -> 20 | C12: =SUMIF(Data_2025!$I:$I,A12,Data_2025!$T:$T) -> 26790 | D12: =IF(B12=0,"",C12/B12) -> 1339.5 | E12: =IF($C$2=0,"",C12/$C$2) -> 0.0019932403 | F12: =_xludf.RANK.EQ(C12,$C$5:$C$21,0) -> #NAME?
A13: انستجرام | B13: =COUNTIF(Data_2025!$I:$I,A13) -> 6 | C13: =SUMIF(Data_2025!$I:$I,A13,Data_2025!$T:$T) -> 6170 | D13: =IF(B13=0,"",C13/B13) -> 1028.3333 | E13: =IF($C$2=0,"",C13/$C$2) -> 0.00045906281 | F13: =_xludf.RANK.EQ(C13,$C$5:$C$21,0) -> #NAME?
A14: اعلان واتساب | B14: =COUNTIF(Data_2025!$I:$I,A14) -> 1 | C14: =SUMIF(Data_2025!$I:$I,A14,Data_2025!$T:$T) -> 3410 | D14: =IF(B14=0,"",C14/B14) -> 3410 | E14: =IF($C$2=0,"",C14/$C$2) -> 0.00025371219 | F14: =_xludf.RANK.EQ(C14,$C$5:$C$21,0) -> #NAME?
A15: إعلان الرقاب | B15: =COUNTIF(Data_2025!$I:$I,A15) -> 3 | C15: =SUMIF(Data_2025!$I:$I,A15,Data_2025!$T:$T) -> 2900 | D15: =IF(B15=0,"",C15/B15) -> 966.66667 | E15: =IF($C$2=0,"",C15/$C$2) -> 0.00021576696 | F15: =_xludf.RANK.EQ(C15,$C$5:$C$21,0) -> #NAME?
A16: اعلانات الواتساب | B16: =COUNTIF(Data_2025!$I:$I,A16) -> 1 | C16: =SUMIF(Data_2025!$I:$I,A16,Data_2025!$T:$T) -> 2060 | D16: =IF(B16=0,"",C16/B16) -> 2060 | E16: =IF($C$2=0,"",C16/$C$2) -> 0.00015326895 | F16: =_xludf.RANK.EQ(C16,$C$5:$C$21,0) -> #NAME?
A17: مكالمات امس | B17: =COUNTIF(Data_2025!$I:$I,A17) -> 1 | C17: =SUMIF(Data_2025!$I:$I,A17,Data_2025!$T:$T) -> 1470 | D17: =IF(B17=0,"",C17/B17) -> 1470 | E17: =IF($C$2=0,"",C17/$C$2) -> 0.00010937153 | F17: =_xludf.RANK.EQ(C17,$C$5:$C$21,0) -> #NAME?
A18: شركه الشحن | B18: =COUNTIF(Data_2025!$I:$I,A18) -> 1 | C18: =SUMIF(Data_2025!$I:$I,A18,Data_2025!$T:$T) -> 1380 | D18: =IF(B18=0,"",C18/B18) -> 1380 | E18: =IF($C$2=0,"",C18/$C$2) -> 0.00010267531 | F18: =_xludf.RANK.EQ(C18,$C$5:$C$21,0) -> #NAME?
A19: شركة الشحن | B19: =COUNTIF(Data_2025!$I:$I,A19) -> 1 | C19: =SUMIF(Data_2025!$I:$I,A19,Data_2025!$T:$T) -> 1350 | D19: =IF(B19=0,"",C19/B19) -> 1350 | E19: =IF($C$2=0,"",C19/$C$2) -> 0.00010044324 | F19: =_xludf.RANK.EQ(C19,$C$5:$C$21,0) -> #NAME?
A20: استلام من المقر | B20: =COUNTIF(Data_2025!$I:$I,A20) -> 1 | C20: =SUMIF(Data_2025!$I:$I,A20,Data_2025!$T:$T) -> 1050 | D20: =IF(B20=0,"",C20/B20) -> 1050 | E20: =IF($C$2=0,"",C20/$C$2) -> 7.8122521e-05 | F20: =_xludf.RANK.EQ(C20,$C$5:$C$21,0) -> #NAME?
A21: مقر شركة الشحن | B21: =COUNTIF(Data_2025!$I:$I,A21) -> 1 | C21: =SUMIF(Data_2025!$I:$I,A21,Data_2025!$T:$T) -> 1050 | D21: =IF(B21=0,"",C21/B21) -> 1050 | E21: =IF($C$2=0,"",C21/$C$2) -> 7.8122521e-05 | F21: =_xludf.RANK.EQ(C21,$C$5:$C$21,0) -> #NAME?
A24: شركة الشحن (Normalized) | Shipping
A25: Category | B25: Orders | C25: Sales | D25: Avg Order | E25: Sales Share % | F25: Rank | H25: Rank | I25: شركة الشحن (Normalized) | J25: Sales
A26: مندوب خاص | B26: =COUNTIF(Data_2025!$K:$K,A26) -> 3328 | C26: =SUMIF(Data_2025!$K:$K,A26,Data_2025!$T:$T) -> 5861709 | D26: =IF(B26=0,"",C26/B26) -> 1761.3308 | E26: =IF($C$2=0,"",C26/$C$2) -> 0.43612522 | F26: =_xludf.RANK.EQ(C26,$C$26:$C$36,0) -> #NAME? | H26: 1 | I26: =INDEX($A$26:$A$36,MATCH(H26,$F$26:$F$36,0)) -> #N/A | J26: =LARGE($C$26:$C$36,H26) -> 5861709
A27: زودكس | B27: =COUNTIF(Data_2025!$K:$K,A27) -> 3522 | C27: =SUMIF(Data_2025!$K:$K,A27,Data_2025!$T:$T) -> 5379071 | D27: =IF(B27=0,"",C27/B27) -> 1527.2774 | E27: =IF($C$2=0,"",C27/$C$2) -> 0.4002158 | F27: =_xludf.RANK.EQ(C27,$C$26:$C$36,0) -> #NAME? | H27: 2 | I27: =INDEX($A$26:$A$36,MATCH(H27,$F$26:$F$36,0)) -> #N/A | J27: =LARGE($C$26:$C$36,H27) -> 5379071
A28: العاصمة | B28: =COUNTIF(Data_2025!$K:$K,A28) -> 869 | C28: =SUMIF(Data_2025!$K:$K,A28,Data_2025!$T:$T) -> 1208835 | D28: =IF(B28=0,"",C28/B28) -> 1391.0644 | E28: =IF($C$2=0,"",C28/$C$2) -> 0.089940226 | F28: =_xludf.RANK.EQ(C28,$C$26:$C$36,0) -> #NAME? | H28: 3 | I28: =INDEX($A$26:$A$36,MATCH(H28,$F$26:$F$36,0)) -> #N/A | J28: =LARGE($C$26:$C$36,H28) -> 1208835
A29: مندوب من المزرعة | B29: =COUNTIF(Data_2025!$K:$K,A29) -> 100 | C29: =SUMIF(Data_2025!$K:$K,A29,Data_2025!$T:$T) -> 550136 | D29: =IF(B29=0,"",C29/B29) -> 5501.36 | E29: =IF($C$2=0,"",C29/$C$2) -> 0.040931439 | F29: =_xludf.RANK.EQ(C29,$C$26:$C$36,0) -> #NAME? | H29: 4 | I29: =INDEX($A$26:$A$36,MATCH(H29,$F$26:$F$36,0)) -> #N/A | J29: =LARGE($C$26:$C$36,H29) -> 550136
A30: استلام من المزرعة | B30: =COUNTIF(Data_2025!$K:$K,A30) -> 168 | C30: =SUMIF(Data_2025!$K:$K,A30,Data_2025!$T:$T) -> 427670.5 | D30: =IF(B30=0,"",C30/B30) -> 2545.6577 | E30: =IF($C$2=0,"",C30/$C$2) -> 0.031819712 | F30: =_xludf.RANK.EQ(C30,$C$26:$C$36,0) -> #NAME? | H30: 5 | I30: =INDEX($A$26:$A$36,MATCH(H30,$F$26:$F$36,0)) -> #N/A | J30: =LARGE($C$26:$C$36,H30) -> 427670.5
A31: مندوب | B31: =COUNTIF(Data_2025!$K:$K,A31) -> 1 | C31: =SUMIF(Data_2025!$K:$K,A31,Data_2025!$T:$T) -> 3500 | D31: =IF(B31=0,"",C31/B31) -> 3500 | E31: =IF($C$2=0,"",C31/$C$2) -> 0.0002604084 | F31: =_xludf.RANK.EQ(C31,$C$26:$C$36,0) -> #NAME?
A32: مندوب من المزرعه | B32: =COUNTIF(Data_2025!$K:$K,A32) -> 1 | C32: =SUMIF(Data_2025!$K:$K,A32,Data_2025!$T:$T) -> 2960 | D32: =IF(B32=0,"",C32/B32) -> 2960 | E32: =IF($C$2=0,"",C32/$C$2) -> 0.00022023111 | F32: =_xludf.RANK.EQ(C32,$C$26:$C$36,0) -> #NAME?
A33: هيجي يستلم من المزرعه | B33: =COUNTIF(Data_2025!$K:$K,A33) -> 1 | C33: =SUMIF(Data_2025!$K:$K,A33,Data_2025!$T:$T) -> 2730 | D33: =IF(B33=0,"",C33/B33) -> 2730 | E33: =IF($C$2=0,"",C33/$C$2) -> 0.00020311855 | F33: =_xludf.RANK.EQ(C33,$C$26:$C$36,0) -> #NAME?
A34: هيسلتم من المزرعه | B34: =COUNTIF(Data_2025!$K:$K,A34) -> 2 | C34: =SUMIF(Data_2025!$K:$K,A34,Data_2025!$T:$T) -> 1935 | D34: =IF(B34=0,"",C34/B34) -> 967.5 | E34: =IF($C$2=0,"",C34/$C$2) -> 0.00014396865 | F34: =_xludf.RANK.EQ(C34,$C$26:$C$36,0) -> #NAME?
A35: هتستلم م المزرعه | B35: =COUNTIF(Data_2025!$K:$K,A35) -> 2 | C35: =SUMIF(Data_2025!$K:$K,A35,Data_2025!$T:$T) -> 1680 | D35: =IF(B35=0,"",C35/B35) -> 840 | E35: =IF($C$2=0,"",C35/$C$2) -> 0.00012499603 | F35: =_xludf.RANK.EQ(C35,$C$26:$C$36,0) -> #NAME?
A36: هتستلم م مزرعه | B36: =COUNTIF(Data_2025!$K:$K,A36) -> 1 | C36: =SUMIF(Data_2025!$K:$K,A36,Data_2025!$T:$T) -> 200 | D36: =IF(B36=0,"",C36/B36) -> 200 | E36: =IF($C$2=0,"",C36/$C$2) -> 1.488048e-05 | F36: =_xludf.RANK.EQ(C36,$C$26:$C$36,0) -> #NAME?
A39: الموديراتور (Normalized) | Moderator
A40: Category | B40: Orders | C40: Sales | D40: Avg Order | E40: Sales Share % | F40: Rank | H40: Rank | I40: الموديراتور (Normalized) | J40: Sales
A41: أية | B41: =COUNTIF(Data_2025!$G:$G,A41) -> 3126 | C41: =SUMIF(Data_2025!$G:$G,A41,Data_2025!$T:$T) -> 5906181 | D41: =IF(B41=0,"",C41/B41) -> 1889.3733 | E41: =IF($C$2=0,"",C41/$C$2) -> 0.43943405 | F41: =_xludf.RANK.EQ(C41,$C$41:$C$54,0) -> #NAME? | H41: 1 | I41: =INDEX($A$41:$A$54,MATCH(H41,$F$41:$F$54,0)) -> #N/A | J41: =LARGE($C$41:$C$54,H41) -> 5906181
A42: هبة | B42: =COUNTIF(Data_2025!$G:$G,A42) -> 1564 | C42: =SUMIF(Data_2025!$G:$G,A42,Data_2025!$T:$T) -> 2192883 | D42: =IF(B42=0,"",C42/B42) -> 1402.0991 | E42: =IF($C$2=0,"",C42/$C$2) -> 0.16315576 | F42: =_xludf.RANK.EQ(C42,$C$41:$C$54,0) -> #NAME? | H42: 2 | I42: =INDEX($A$41:$A$54,MATCH(H42,$F$41:$F$54,0)) -> #N/A | J42: =LARGE($C$41:$C$54,H42) -> 2192883
A43: رانيا | B43: =COUNTIF(Data_2025!$G:$G,A43) -> 1025 | C43: =SUMIF(Data_2025!$G:$G,A43,Data_2025!$T:$T) -> 1816397.5 | D43: =IF(B43=0,"",C43/B43) -> 1772.0951 | E43: =IF($C$2=0,"",C43/$C$2) -> 0.13514433 | F43: =_xludf.RANK.EQ(C43,$C$41:$C$54,0) -> #NAME? | H43: 3 | I43: =INDEX($A$41:$A$54,MATCH(H43,$F$41:$F$54,0)) -> #N/A | J43: =LARGE($C$41:$C$54,H43) -> 1816397.5
A44: سارة | B44: =COUNTIF(Data_2025!$G:$G,A44) -> 1235 | C44: =SUMIF(Data_2025!$G:$G,A44,Data_2025!$T:$T) -> 1779863 | D44: =IF(B44=0,"",C44/B44) -> 1441.1846 | E44: =IF($C$2=0,"",C44/$C$2) -> 0.13242608 | F44: =_xludf.RANK.EQ(C44,$C$41:$C$54,0) -> #NAME? | H44: 4 | I44: =INDEX($A$41:$A$54,MATCH(H44,$F$41:$F$54,0)) -> #N/A | J44: =LARGE($C$41:$C$54,H44) -> 1779863
...

Sheet Products
A1: تحليل المنتجات | Product Mix (Qty)
B2: Total Orders | C2: =COUNTA(Data_2025!$A:$A)-1 -> 7995
A3: Product | B3: Total Qty | C3: Orders With Product | D3: % of Orders | E3: Avg Qty / Product Order | F3: Rank | H3: Rank | I3: Product | J3: Total Qty | K3: Orders
A4: اللحم | B4: =SUM(Data_2025!$Z:$Z) -> 11185 | C4: =COUNTIF(Data_2025!$Z:$Z,">0") -> 4256 | D4: =IF($C$2=0,"",C4/$C$2) -> 0.53233271 | E4: =IF(C4=0,"",B4/C4) -> 2.6280545 | F4: =_xludf.RANK.EQ(B4,$B$4:$B$39,0) -> #NAME? | H4: 1 | I4: =INDEX($A$4:$A$39,MATCH(H4,$F$4:$F$39,0)) -> #N/A | J4: =LARGE($B$4:$B$39,H4) -> 15489 | K4: =INDEX($C$4:$C$39,MATCH(H4,$F$4:$F$39,0)) -> #N/A
A5: الاستيك | B5: =SUM(Data_2025!$AA:$AA) -> 5668 | C5: =COUNTIF(Data_2025!$AA:$AA,">0") -> 2858 | D5: =IF($C$2=0,"",C5/$C$2) -> 0.35747342 | E5: =IF(C5=0,"",B5/C5) -> 1.983205 | F5: =_xludf.RANK.EQ(B5,$B$4:$B$39,0) -> #NAME? | H5: 2 | I5: =INDEX($A$4:$A$39,MATCH(H5,$F$4:$F$39,0)) -> #N/A | J5: =LARGE($B$4:$B$39,H5) -> 11185 | K5: =INDEX($C$4:$C$39,MATCH(H5,$F$4:$F$39,0)) -> #N/A
A6: الموزه | B6: =SUM(Data_2025!$AB:$AB) -> 4388 | C6: =COUNTIF(Data_2025!$AB:$AB,">0") -> 2072 | D6: =IF($C$2=0,"",C6/$C$2) -> 0.25916198 | E6: =IF(C6=0,"",B6/C6) -> 2.1177606 | F6: =_xludf.RANK.EQ(B6,$B$4:$B$39,0) -> #NAME? | H6: 3 | I6: =INDEX($A$4:$A$39,MATCH(H6,$F$4:$F$39,0)) -> #N/A | J6: =LARGE($B$4:$B$39,H6) -> 7259 | K6: =INDEX($C$4:$C$39,MATCH(H6,$F$4:$F$39,0)) -> #N/A
A7: الفراشه | B7: =SUM(Data_2025!$AC:$AC) -> 656 | C7: =COUNTIF(Data_2025!$AC:$AC,">0") -> 285 | D7: =IF($C$2=0,"",C7/$C$2) -> 0.03564728 | E7: =IF(C7=0,"",B7/C7) -> 2.3017544 | F7: =_xludf.RANK.EQ(B7,$B$4:$B$39,0) -> #NAME? | H7: 4 | I7: =INDEX($A$4:$A$39,MATCH(H7,$F$4:$F$39,0)) -> #N/A | J7: =LARGE($B$4:$B$39,H7) -> 7054 | K7: =INDEX($C$4:$C$39,MATCH(H7,$F$4:$F$39,0)) -> #N/A
A8: قطعية الدبوس | B8: =SUM(Data_2025!$AD:$AD) -> 1207 | C8: =COUNTIF(Data_2025!$AD:$AD,">0") -> 538 | D8: =IF($C$2=0,"",C8/$C$2) -> 0.067292058 | E8: =IF(C8=0,"",B8/C8) -> 2.2434944 | F8: =_xludf.RANK.EQ(B8,$B$4:$B$39,0) -> #NAME? | H8: 5 | I8: =INDEX($A$4:$A$39,MATCH(H8,$F$4:$F$39,0)) -> #N/A | J8: =LARGE($B$4:$B$39,H8) -> 6780 | K8: =INDEX($C$4:$C$39,MATCH(H8,$F$4:$F$39,0)) -> #N/A
A9: قطعية التريبيانكو | B9: =SUM(Data_2025!$AE:$AE) -> 982 | C9: =COUNTIF(Data_2025!$AE:$AE,">0") -> 359 | D9: =IF($C$2=0,"",C9/$C$2) -> 0.044903064 | E9: =IF(C9=0,"",B9/C9) -> 2.735376 | F9: =_xludf.RANK.EQ(B9,$B$4:$B$39,0) -> #NAME? | H9: 6 | I9: =INDEX($A$4:$A$39,MATCH(H9,$F$4:$F$39,0)) -> #N/A | J9: =LARGE($B$4:$B$39,H9) -> 6630 | K9: =INDEX($C$4:$C$39,MATCH(H9,$F$4:$F$39,0)) -> #N/A
A10: قطعية الاسكلوب | B10: =SUM(Data_2025!$AF:$AF) -> 750 | C10: =COUNTIF(Data_2025!$AF:$AF,">0") -> 274 | D10: =IF($C$2=0,"",C10/$C$2) -> 0.03427142 | E10: =IF(C10=0,"",B10/C10) -> 2.7372263 | F10: =_xludf.RANK.EQ(B10,$B$4:$B$39,0) -> #NAME? | H10: 7 | I10: =INDEX($A$4:$A$39,MATCH(H10,$F$4:$F$39,0)) -> #N/A | J10: =LARGE($B$4:$B$39,H10) -> 5668 | K10: =INDEX($C$4:$C$39,MATCH(H10,$F$4:$F$39,0)) -> #N/A
A11: ميت رول | B11: =SUM(Data_2025!$AG:$AG) -> 176 | C11: =COUNTIF(Data_2025!$AG:$AG,">0") -> 77 | D11: =IF($C$2=0,"",C11/$C$2) -> 0.0096310194 | E11: =IF(C11=0,"",B11/C11) -> 2.2857143 | F11: =_xludf.RANK.EQ(B11,$B$4:$B$39,0) -> #NAME? | H11: 8 | I11: =INDEX($A$4:$A$39,MATCH(H11,$F$4:$F$39,0)) -> #N/A | J11: =LARGE($B$4:$B$39,H11) -> 4388 | K11: =INDEX($C$4:$C$39,MATCH(H11,$F$4:$F$39,0)) -> #N/A
A12: الكبده | B12: =SUM(Data_2025!$AH:$AH) -> 1840.335 | C12: =COUNTIF(Data_2025!$AH:$AH,">0") -> 1012 | D12: =IF($C$2=0,"",C12/$C$2) -> 0.12657911 | E12: =IF(C12=0,"",B12/C12) -> 1.8185128 | F12: =_xludf.RANK.EQ(B12,$B$4:$B$39,0) -> #NAME? | H12: 9 | I12: =INDEX($A$4:$A$39,MATCH(H12,$F$4:$F$39,0)) -> #N/A | J12: =LARGE($B$4:$B$39,H12) -> 4363 | K12: =INDEX($C$4:$C$39,MATCH(H12,$F$4:$F$39,0)) -> #N/A
A13: القلب | B13: =SUM(Data_2025!$AI:$AI) -> 1866 | C13: =COUNTIF(Data_2025!$AI:$AI,">0") -> 574 | D13: =IF($C$2=0,"",C13/$C$2) -> 0.071794872 | E13: =IF(C13=0,"",B13/C13) -> 3.2508711 | F13: =_xludf.RANK.EQ(B13,$B$4:$B$39,0) -> #NAME? | H13: 10 | I13: =INDEX($A$4:$A$39,MATCH(H13,$F$4:$F$39,0)) -> #N/A | J13: =LARGE($B$4:$B$39,H13) -> 2903 | K13: =INDEX($C$4:$C$39,MATCH(H13,$F$4:$F$39,0)) -> #N/A
A14: القوانص | B14: =SUM(Data_2025!$AJ:$AJ) -> 2181 | C14: =COUNTIF(Data_2025!$AJ:$AJ,">0") -> 790 | D14: =IF($C$2=0,"",C14/$C$2) -> 0.098811757 | E14: =IF(C14=0,"",B14/C14) -> 2.7607595 | F14: =_xludf.RANK.EQ(B14,$B$4:$B$39,0) -> #NAME?
A15: الرقاب | B15: =SUM(Data_2025!$AK:$AK) -> 4363 | C15: =COUNTIF(Data_2025!$AK:$AK,">0") -> 1866 | D15: =IF($C$2=0,"",C15/$C$2) -> 0.23339587 | E15: =IF(C15=0,"",B15/C15) -> 2.3381565 | F15: =_xludf.RANK.EQ(B15,$B$4:$B$39,0) -> #NAME?
A16: الدهن | B16: =SUM(Data_2025!$AL:$AL) -> 2109 | C16: =COUNTIF(Data_2025!$AL:$AL,">0") -> 316 | D16: =IF($C$2=0,"",C16/$C$2) -> 0.039524703 | E16: =IF(C16=0,"",B16/C16) -> 6.6740506 | F16: =_xludf.RANK.EQ(B16,$B$4:$B$39,0) -> #NAME?
A17: الكوارع | B17: =SUM(Data_2025!$AM:$AM) -> 1324 | C17: =COUNTIF(Data_2025!$AM:$AM,">0") -> 628 | D17: =IF($C$2=0,"",C17/$C$2) -> 0.078549093 | E17: =IF(C17=0,"",B17/C17) -> 2.1082803 | F17: =_xludf.RANK.EQ(B17,$B$4:$B$39,0) -> #NAME?
A18: كفتة | B18: =SUM(Data_2025!$AN:$AN) -> 7054 | C18: =COUNTIF(Data_2025!$AN:$AN,">0") -> 3473 | D18: =IF($C$2=0,"",C18/$C$2) -> 0.4343965 | E18: =IF(C18=0,"",B18/C18) -> 2.031097 | F18: =_xludf.RANK.EQ(B18,$B$4:$B$39,0) -> #NAME?
A19: سجق | B19: =SUM(Data_2025!$AO:$AO) -> 6780 | C19: =COUNTIF(Data_2025!$AO:$AO,">0") -> 3366 | D19: =IF($C$2=0,"",C19/$C$2) -> 0.42101313 | E19: =IF(C19=0,"",B19/C19) -> 2.0142602 | F19: =_xludf.RANK.EQ(B19,$B$4:$B$39,0) -> #NAME?
A20: برجر | B20: =SUM(Data_2025!$AP:$AP) -> 7259 | C20: =COUNTIF(Data_2025!$AP:$AP,">0") -> 3396 | D20: =IF($C$2=0,"",C20/$C$2) -> 0.42476548 | E20: =IF(C20=0,"",B20/C20) -> 2.1375147 | F20: =_xludf.RANK.EQ(B20,$B$4:$B$39,0) -> #NAME?
A21: لانشون سادة | B21: =SUM(Data_2025!$AQ:$AQ) -> 911 | C21: =COUNTIF(Data_2025!$AQ:$AQ,">0") -> 404 | D21: =IF($C$2=0,"",C21/$C$2) -> 0.050531582 | E21: =IF(C21=0,"",B21/C21) -> 2.2549505 | F21: =_xludf.RANK.EQ(B21,$B$4:$B$39,0) -> #NAME?
A22: لانشون بالفلفل الاسود | B22: =SUM(Data_2025!$AR:$AR) -> 2 | C22: =COUNTIF(Data_2025!$AR:$AR,">0") -> 1 | D22: =IF($C$2=0,"",C22/$C$2) -> 0.00012507817 | E22: =IF(C22=0,"",B22/C22) -> 2 | F22: =_xludf.RANK.EQ(B22,$B$4:$B$39,0) -> #NAME?
A23: لانشون ببروني | B23: =SUM(Data_2025!$AS:$AS) -> 6 | C23: =COUNTIF(Data_2025!$AS:$AS,">0") -> 1 | D23: =IF($C$2=0,"",C23/$C$2) -> 0.00012507817 | E23: =IF(C23=0,"",B23/C23) -> 6 | F23: =_xludf.RANK.EQ(B23,$B$4:$B$39,0) -> #NAME?
A24: مفروم حواوشي | B24: =SUM(Data_2025!$AT:$AT) -> 6630 | C24: =COUNTIF(Data_2025!$AT:$AT,">0") -> 3431 | D24: =IF($C$2=0,"",C24/$C$2) -> 0.42914321 | E24: =IF(C24=0,"",B24/C24) -> 1.9323812 | F24: =_xludf.RANK.EQ(B24,$B$4:$B$39,0) -> #NAME?
A25: مفروم | B25: =SUM(Data_2025!$AU:$AU) -> 2783 | C25: =COUNTIF(Data_2025!$AU:$AU,">0") -> 1311 | D25: =IF($C$2=0,"",C25/$C$2) -> 0.16397749 | E25: =IF(C25=0,"",B25/C25) -> 2.122807 | F25: =_xludf.RANK.EQ(B25,$B$4:$B$39,0) -> #NAME?
A26: كريم المفاصل | B26: =SUM(Data_2025!$AV:$AV) -> 0 | C26: =COUNTIF(Data_2025!$AV:$AV,">0") -> 0 | D26: =IF($C$2=0,"",C26/$C$2) -> 0 | E26: =IF(C26=0,"",B26/C26) | F26: =_xludf.RANK.EQ(B26,$B$4:$B$39,0) -> #NAME?
A27: زيت الشعر ( سيدات ) | B27: =SUM(Data_2025!$AW:$AW) -> 0 | C27: =COUNTIF(Data_2025!$AW:$AW,">0") -> 0 | D27: =IF($C$2=0,"",C27/$C$2) -> 0 | E27: =IF(C27=0,"",B27/C27) | F27: =_xludf.RANK.EQ(B27,$B$4:$B$39,0) -> #NAME?
A28: كريم الشعر ( رجال ) | B28: =SUM(Data_2025!$AX:$AX) -> 2 | C28: =COUNTIF(Data_2025!$AX:$AX,">0") -> 1 | D28: =IF($C$2=0,"",C28/$C$2) -> 0.00012507817 | E28: =IF(C28=0,"",B28/C28) -> 2 | F28: =_xludf.RANK.EQ(B28,$B$4:$B$39,0) -> #NAME?
A29: كريم للبشرة | B29: =SUM(Data_2025!$AY:$AY) -> 15489 | C29: =COUNTIF(Data_2025!$AY:$AY,">0") -> 2 | D29: =IF($C$2=0,"",C29/$C$2) -> 0.00025015635 | E29: =IF(C29=0,"",B29/C29) -> 7744.5 | F29: =_xludf.RANK.EQ(B29,$B$4:$B$39,0) -> #NAME?
A30: لحم غزال | B30: =SUM(Data_2025!$AZ:$AZ) -> 0 | C30: =COUNTIF(Data_2025!$AZ:$AZ,">0") -> 0 | D30: =IF($C$2=0,"",C30/$C$2) -> 0 | E30: =IF(C30=0,"",B30/C30) | F30: =_xludf.RANK.EQ(B30,$B$4:$B$39,0) -> #NAME?
A31: شاورما | B31: =SUM(Data_2025!$BA:$BA) -> 2903 | C31: =COUNTIF(Data_2025!$BA:$BA,">0") -> 1897 | D31: =IF($C$2=0,"",C31/$C$2) -> 0.2372733 | E31: =IF(C31=0,"",B31/C31) -> 1.530311 | F31: =_xludf.RANK.EQ(B31,$B$4:$B$39,0) -> #NAME?
A32: كباب | B32: =SUM(Data_2025!$BB:$BB) -> 257 | C32: =COUNTIF(Data_2025!$BB:$BB,">0") -> 135 | D32: =IF($C$2=0,"",C32/$C$2) -> 0.016885553 | E32: =IF(C32=0,"",B32/C32) -> 1.9037037 | F32: =_xludf.RANK.EQ(B32,$B$4:$B$39,0) -> #NAME?
A33: شيش | B33: =SUM(Data_2025!$BC:$BC) -> 800 | C33: =COUNTIF(Data_2025!$BC:$BC,">0") -> 567 | D33: =IF($C$2=0,"",C33/$C$2) -> 0.070919325 | E33: =IF(C33=0,"",B33/C33) -> 1.4109347 | F33: =_xludf.RANK.EQ(B33,$B$4:$B$39,0) -> #NAME?
A34: ممبار | B34: =SUM(Data_2025!$BD:$BD) -> 9 | C34: =COUNTIF(Data_2025!$BD:$BD,">0") -> 3 | D34: =IF($C$2=0,"",C34/$C$2) -> 0.00037523452 | E34: =IF(C34=0,"",B34/C34) -> 3 | F34: =_xludf.RANK.EQ(B34,$B$4:$B$39,0) -> #NAME?
A35: كفتة أرز | B35: =SUM(Data_2025!$BE:$BE) -> 21 | C35: =COUNTIF(Data_2025!$BE:$BE,">0") -> 10 | D35: =IF($C$2=0,"",C35/$C$2) -> 0.0012507817 | E35: =IF(C35=0,"",B35/C35) -> 2.1 | F35: =_xludf.RANK.EQ(B35,$B$4:$B$39,0) -> #NAME?
A36: بيض | B36: =SUM(Data_2025!$BF:$BF) -> 41 | C36: =COUNTIF(Data_2025!$BF:$BF,">0") -> 27 | D36: =IF($C$2=0,"",C36/$C$2) -> 0.0033771107 | E36: =IF(C36=0,"",B36/C36) -> 1.5185185 | F36: =_xludf.RANK.EQ(B36,$B$4:$B$39,0) -> #NAME?
A37: دبوس 7 كيلو | B37: =SUM(Data_2025!$BG:$BG) -> 155 | C37: =COUNTIF(Data_2025!$BG:$BG,">0") -> 141 | D37: =IF($C$2=0,"",C37/$C$2) -> 0.017636023 | E37: =IF(C37=0,"",B37/C37) -> 1.0992908 | F37: =_xludf.RANK.EQ(B37,$B$4:$B$39,0) -> #NAME?
A38: طرب | B38: =SUM(Data_2025!$BH:$BH) -> 177 | C38: =COUNTIF(Data_2025!$BH:$BH,">0") -> 88 | D38: =IF($C$2=0,"",C38/$C$2) -> 0.011006879 | E38: =IF(C38=0,"",B38/C38) -> 2.0113636 | F38: =_xludf.RANK.EQ(B38,$B$4:$B$39,0) -> #NAME?
A39: برجر بالجبنة | B39: =SUM(Data_2025!$BI:$BI) -> 10 | C39: =COUNTIF(Data_2025!$BI:$BI,">0") -> 4 | D39: =IF($C$2=0,"",C39/$C$2) -> 0.0005003127 | E39: =IF(C39=0,"",B39/C39) -> 2.5 | F39: =_xludf.RANK.EQ(B39,$B$4:$B$39,0) -> #NAME?

Sheet Data_Quality
A1: جودة البيانات | Data Quality & Exceptions
A2: Key Checks | D2: Top Repeat Customers (by Phone)
A3: Total Orders | B3: 7995 | D3: Customer Phone | E3: Orders
A4: Total Sales (EGP) | B4: 13440426 | D4: 01091348942 | E4: 9
A5: Missing/Invalid Timestamp | B5: 1 | D5: 01093308208 | E5: 9
A6: Timestamp Month ≠ Sheet Month | B6: 31 | D6: 1005305500 | E6: 8
A7: Product Qty Outliers > 100 | B7: 15 | D7: 01554027727 | E7: 8
A8: Orders with Big Item only (no qty) | B8: 179 | D8: 01111247283 | E8: 7
D9: 01061586791 | E9: 6
D10: 01098451177 | E10: 6
D11: 01099386139 | E11: 6
D12: 01222600972 | E12: 5
D13: 01221873076 | E13: 5
D14: 01143410961 | E14: 5
D15: 01068944454 | E15: 5
D16: 01550871870 | E16: 5
D17: 01281551136 | E17: 5
D18: 01000738858 | E18: 4
D19: 01022333949 | E19: 4
D20: 01033700293 | E20: 4
... D23: 01005537691 | E23: 4
A26: Exceptions (sample)
A27: Issue | B27: OrderID | C27: MonthNo | D27: OrderDateTime | E27: Customer Name | F27: Customer Phone | G27: Governorate | H27: Shipping | I27: OrderValue | J27: TotalItems | K27: BigItem_Desc | L27: SheetName | M27: SourceRow | N27: OutlierProduct | O27: OutlierValue
A28: Missing/Invalid Timestamp | B28: 459 | C28: 2 | E28: محمد حمدى | F28: 1201286017 | G28: كفر الشيخ | H28: مندوب خاص | I28: 2450 | J28: 19 | K28: nan | L28: فبراير 2025 | M28: 65
A29: Timestamp Month ≠ Sheet Month | B29: 3 | C29: 12 | D29: 46021 | E29: اوردر الفخده | F29: 1002838784 | G29: القاهرة | H29: مندوب خاص | I29: 14430 | J29: 0 | K29: فخدتين | nan | L29: يناير 2025 | M29: 4
A30: Timestamp Month ≠ Sheet Month | B30: 451 | C30: 3 | D30: 45717.037 | E30: محمد علي | F30: 01001500624 | G30: الجيزة | H30: زودكس | I30: 1550 | J30: 6 | K30: nan | L30: فبراير 2025 | M30: 57
A31: Timestamp Month ≠ Sheet Month | B31: 675 | C31: 3 | D31: 45717.017 | E31: عبير إبراهيم | F31: 01118181087 | G31: القاهرة | H31: زودكس | I31: 2230 | J31: 18 | K31: nan | L31: فبراير 2025 | M31: 281
A32: Timestamp Month ≠ Sheet Month | B32: 676 | C32: 3 | D32: 45717.028 | E32: محمود صلاح | F32: 01092888588 | G32: القاهرة | H32: زودكس | I32: 1305 | J32: 6 | K32: nan | L32: فبراير 2025 | M32: 282
A33: Timestamp Month ≠ Sheet Month | B33: 677 | C33: 3 | D33: 45717.03 | E33: دارا سمير محمد | F33: 01033773343 | G33: القاهرة | H33: زودكس | I33: 1360 | J33: 6 | K33: nan | L33: فبراير 2025 | M33: 283
A34: Timestamp Month ≠ Sheet Month | B34: 678 | C34: 3 | D34: 45717.062 | E34: صفاء فوزي | F34: 1220802055 | G34: الغربية | H34: مندوب خاص | I34: 1550 | J34: 12 | K34: nan | L34: فبراير 2025 | M34: 284
A35: Timestamp Month ≠ Sheet Month | B35: 1227 | C35: 3 | D35: 45717.058 | E35: يوسف احمد | F35: 01110179737 | G35: الغربية | H35: مندوب خاص | I35: 735 | J35: 3 | K35: nan | L35: فبراير 2025 | M35: 834
A36: Timestamp Month ≠ Sheet Month | B36: 1558 | C36: 4 | D36: 45748.047 | E36: بيشوي القس هدرا | F36: 1015793157 | G36: الدقهلية | H36: مندوب خاص | I36: 5205 | J36: 17 | K36: دبوس 7 كيلو | nan | L36: مارس 2025 | M36: 332
A37: Timestamp Month ≠ Sheet Month | B37: 3131 | C37: 6 | D37: 45838.649 | E37: محمود توفيق | F37: 01005763417 | G37: الغربية | H37: مندوب من المزرعة | I37: 2195 | J37: 12 | K37: nan | L37: يوليو2025 | M37: 2
A38: Timestamp Month ≠ Sheet Month | B38: 3132 | C38: 6 | D38: 45838.651 | E38: محمود عبدالموالي | F38: 01031033623 | G38: الدقهلية | H38: مندوب خاص | I38: 2450 | J38: 0 | K38: دبوس ٧ كيلو | nan | L38: يوليو2025 | M38: 3
A39: Timestamp Month ≠ Sheet Month | B39: 3133 | C39: 6 | D39: 45838.653 | E39: عبدالمنصف التركي | F39: 01003994187 | G39: الإسكندرية | H39: مندوب خاص | I39: 1880 | J39: 8 | K39: nan | L39: يوليو2025 | M39: 4
A40: Timestamp Month ≠ Sheet Month | B40: 3134 | C40: 6 | D40: 45838.662 | E40: رامي الراوي | F40: 01094452800 | G40: القاهرة | H40: زودكس | I40: 900 | J40: 8 | K40: nan | L40: يوليو2025 | M40: 5
... A59: Timestamp Month ≠ Sheet Month | B59: 7282 | C59: 12 | D59: 45992.11 | E59: تغريد فتحي | F59: 01003640066 | G59: القاهرة | H59: العاصمة | I59: 1000 | J59: 7 | K59: nan | L59: نوفمبر 2025 | M59: 665
A60: Product Qty Outlier > 100 | B60: 40 | C60: 1 | D60: 45659.851 | E60: اسلام | F60: 1005305500 | G60: الإسكندرية | H60: مندوب خاص | I60: 42000 | J60: 200 | K60: nan | L60: يناير 2025 | M60: 41 | N60: اللحم | O60: 200
A61: Product Qty Outlier > 100 | B61: 66 | C61: 1 | D61: 45662.724 | E61: اسلام الشربيني | F61: 1005305500 | G61: الإسكندرية | H61: مندوب خاص | I61: 42000 | J61: 200 | K61: nan | L61: يناير 2025 | M61: 67 | N61: اللحم | O61: 200
A62: Product Qty Outlier > 100 | B62: 144 | C62: 1 | D62: 45667.878 | E62: اسلام الشربيني | F62: 1005305500 | G62: الإسكندرية | H62: مندوب خاص | I62: 47460 | J62: 226 | K62: nan | L62: يناير 2025 | M62: 145 | N62: اللحم | O62: 226
...

Sheet Data_2025
A1: OrderID | B1: YearNo | C1: MonthNo | D1: MonthNameAR | E1: OrderDateTime | F1: Moderator | G1: Moderator_Norm | H1: Customer Source | I1: Source_Norm | J1: Shipping Company | K1: Shipping_Norm | L1: Governorate | M1: Governorate_Norm | N1: City/Centre | O1: Page | P1: Customer Name | Q1: Customer Phone | R1: Customer Phone 2 | S1: Address | T1: OrderValue | U1: TotalItems | V1: HasBigItem | W1: BigItem_Desc | X1: SheetName | Y1: SourceRow | Z1: اللحم | AA1: الاستيك | AB1: الموزه | AC1: الفراشه | AD1: قطعية الدبوس | AE1: قطعية التريبيانكو | AF1: قطعية الاسكلوب | AG1: ميت رول | AH1: الكبده | AI1: القلب | AJ1: القوانص | AK1: الرقاب | AL1: الدهن | AM1: الكوارع | AN1: كفتة | AO1: سجق | AP1: برجر | AQ1: لانشون سادة | AR1: لانشون بالفلفل الاسود | AS1: لانشون ببروني | AT1: مفروم حواوشي | AU1: مفروم | AV1: كريم المفاصل | AW1: زيت الشعر ( سيدات ) | AX1: كريم الشعر ( رجال ) | AY1: كريم للبشرة | AZ1: لحم غزال | BA1: شاورما | BB1: كباب | BC1: شيش | BD1: ممبار | BE1: كفتة أرز | BF1: بيض | BG1: دبوس 7 كيلو | BH1: طرب | BI1: برجر بالجبنة
A2: 1 | B2: 2025 | C2: 1 | D2: يناير | E2: 45687.721 | F2: آيه | G2: أية | H2: مكالمة / واتساب | I2: مكالمة / واتساب | J2: مندوب خاص | K2: مندوب خاص | L2: القليوبية | M2: القليوبية | N2: شبرا الخيمه | P2: طارق | Q2: 1288799701 | S2: 11 ش بدوي محمود متفرع من كريستال عصفور | T2: 870 | U2: 4 | V2: 1 | W2: nan | X2: يناير 2025 | Y2: 2 | AA2: 2 | AB2: 2
A3: 2 | B3: 2025 | C3: 1 | D3: يناير | E3: 45688.767 | F3: آيه | G3: أية | H3: مكالمة / واتساب | I3: مكالمة / واتساب | J3: مندوب خاص | K3: مندوب خاص | L3: الشرقية | M3: الشرقية | N3: بلبيس | P3: محمود العتيق | Q3: 1013744343 | R3: 1064557750 | S3: بلبيس | T3: 1120 | U3: 7 | V3: 1 | W3: nan | X3: يناير 2025 | Y3: 3 | Z3: 3 | AH3: 1 | AI3: 1 | AJ3: 2
A4: 3 | B4: 2025 | C4: 12 | D4: ديسمبر | E4: 46021 | F4: رانيا | G4: رانيا | H4: مكالمة / واتساب | I4: مكالمة / واتساب | J4: مندوب خاص | K4: مندوب خاص | L4: القاهرة | M4: القاهرة | N4: حلوان | P4: اوردر الفخده | Q4: 1002838784 | S4: ٦٣ شارع رشدي المعصرة حلوان القاهرة | T4: 14430 | U4: 0 | V4: 1 | W4: فخدتين | nan | X4: يناير 2025 | Y4: 4
A5: 4 | B5: 2025 | C5: 1 | D5: يناير | E5: 45680.857 | F5: رانيا | G5: رانيا | H5: مكالمة / واتساب | I5: مكالمة / واتساب | J5: مندوب خاص | K5: مندوب خاص | L5: البحيرة | M5: البحيرة | N5: كفر الدوار | P5: مينا محب | Q5: 1201761509 | S5: البحيره كفر الدوار صيدليه مينا محب 15 شارع اسماعيل شحاته منطقه بولس امام الضمان الاجتماعي | T5: 180 | U5: 2 | V5: 1 | W5: nan | X5: يناير 2025 | Y5: 5 | AL5: 2
A6: 5 | B6: 2025 | C6: 1 | D6: يناير | E6: 45681.991 | F6: رانيا | G6: رانيا | H6: مكالمة / واتساب | I6: مكالمة / واتساب | J6: مندوب خاص | K6: مندوب خاص | L6: البحيرة | M6: البحيرة | N6: كفر الدوار | P6: الأمير فؤاد غطاس | Q6: 1224127622 | S6: العنوان/ كفر الدوار الحدائق شارع مدرسة الفرنسيسكان برج الكرمة فوق جم فاروس | T6: 100 | U6: 2 | V6: 1 | W6: nan | X6: يناير 2025 | Y6: 6 | AL6: 2
A7: 6 | B7: 2025 | C7: 1 | D7: يناير | E7: 45683.601 | F7: رانيا | G7: رانيا | H7: مكالمة / واتساب | I7: مكالمة / واتساب | J7: مندوب خاص | K7: مندوب خاص | L7: البحيرة | M7: البحيرة | N7: البحيره | P7: زياد مصطفى | Q7: 1060919135 | S7: دمنهور البحيرة خلف النادى الاجتماعى برج اللقانى الدور الخامس اعلى ماركت طيبة | T7: 2085 | U7: 10 | V7: 1 | W7: nan | X7: يناير 2025 | Y7: 7 | AA7: 6 | AP7: 4
A8: 7 | B8: 2025 | C8: 1 | D8: يناير | E8: 45686.713 | F8: آيه | G8: أية | H8: فيسبوك | I8: فيسبوك | J8: مندوب خاص | K8: مندوب خاص | L8: البحيرة | M8: البحيرة | N8: كفر الدوار | P8: محمد سعيد | Q8: 1005511624 | S8: البحيره كفر الدوار | T8: 1090 | U8: 5 | V8: 1 | W8: nan | X8: يناير 2025 | Y8: 8 | Z8: 4 | AB8: 1
A9: 8 | B9: 2025 | C9: 1 | D9: يناير | E9: 45683.008 | F9: سهيله | G9: سهيلة | H9: فيسبوك | I9: فيسبوك | J9: زودكس | K9: زودكس | L9: القاهرة | M9: القاهرة | N9: القاهرة | P9: زياد حسام | Q9: 1156666757 | S9: المعادى ٤٥ عمارات النخيل ، مدخل شمال الدور الاول شقه ٦ | T9: 435 | U9: 2 | V9: 1 | W9: nan | X9: يناير 2025 | Y9: 9 | Z9: 2
A10: 9 | B10: 2025 | C10: 1 | D10: يناير | E10: 45685.948 | F10: سهيله | G10: سهيلة | H10: فيسبوك | I10: فيسبوك | J10: زودكس | K10: زودكس | L10: القاهرة | M10: القاهرة | N10: القاهرة | P10: أنس صابر | Q10: 1026523546 | R10: 1111014901 | S10: مدينة الضباط المستقبل أمام أكوا بارك قطاع اليو عمارة ٤٥٦ شقة 12 أمام سوبر ماركت القاسم | T10: 5377 | U10: 29 | V10: 1 | W10: nan | X10: يناير 2025 | Y10: 10 | AA10: 6 | AE10: 6 | AF10: 5 | AH10: 6 | AJ10: 6
A11: 10 | B11: 2025 | C11: 1 | D11: يناير | E11: 45686.981 | F11: سهيله | G11: سهيلة | H11: فيسبوك | I11: فيسبوك | J11: زودكس | K11: زودكس | L11: القاهرة | M11: القاهرة | N11: القاهرة | P11: محمود الجمل | Q11: 1004123434 | S11: ٤ش رشاد عبد الهادي دارالسلام بجوار التوحيد والنور القاهره | T11: 870 | U11: 4 | V11: 1 | W11: nan | X11: يناير 2025 | Y11: 11 | AB11: 2 | AD11: 2
A12: 11 | B12: 2025 | C12: 1 | D12: يناير | E12: 45687.698 | F12: آيه | G12: أية | H12: مكالمة / واتساب | I12: مكالمة / واتساب | J12: زودكس | K12: زودكس | L12: القاهرة | M12: القاهرة | N12: الهضبه الوسطى | P12: ماجد | Q12: 1015015395 | R12: 1206461771 | S12: كمبوند النخيل دائري المعادي بجوار وان قطاميه ميدان محمد زكي عماره47مدخل شمال الدور6شقه9القاهره الهضبه الوسطي | T12: 2300 | U12: 12 | V12: 1 | W12: nan | X12: يناير 2025 | Y12: 12 | Z12: 4 | AA12: 2 | AC12: 2 | AU12: 4
A13: 12 | B13: 2025 | C13: 1 | D13: يناير | E13: 45676.917 | F13: سهيله | G13: سهيلة | H13: فيسبوك | I13: فيسبوك | J13: مندوب خاص | K13: مندوب خاص | L13: دمياط | M13: دمياط | N13: دمياط الجديده | P13: عبدالمجيد | Q13: 1556008887 | S13: دمياط الجديده دار مصر ٢ عماره ١٥١ شقه ٥ | T13: 1500 | U13: 10 | V13: 1 | W13: nan | X13: يناير 2025 | Y13: 13 | AH13: 10
A14: 13 | B14: 2025 | C14: 1 | D14: يناير | E14: 45682.969 | F14: آيه | G14: أية | H14: مكالمة / واتساب | I14: مكالمة / واتساب | J14: مندوب خاص | K14: مندوب خاص | L14: القليوبية | M14: القليوبية | N14: طوخ | P14: ممدوح | Q14: 1006119440 | S14: العمار بنها طوخ | T14: 5150 | U14: 30 | V14: 1 | W14: nan | X14: يناير 2025 | Y14: 14 | AB14: 10 | AE14: 10 | AM14: 10
A15: 14 | B15: 2025 | C15: 1 | D15: يناير | E15: 45683.616 | F15: رانيا | G15: رانيا | H15: مكالمة / واتساب | I15: مكالمة / واتساب | J15: زودكس | K15: زودكس | L15: البحيرة | M15: البحيرة | N15: كوم حماده | P15: محمد ابراهيم عليوه | Q15: 1140399489 | R15: 1201050341 | S15: البحيرة - مركز كوم حماده - قرية شبرا اوسيم | T15: 870 | U15: 4 | V15: 1 | W15: nan | X15: يناير 2025 | Y15: 15 | Z15: 4
A16: 15 | B16: 2025 | C16: 1 | D16: يناير | E16: 45685.8 | F16: رانيا | G16: رانيا | H16: مكالمة / واتساب | I16: مكالمة / واتساب | J16: مندوب خاص | K16: مندوب خاص | L16: الغربية | M16: الغربية | N16: المحله الكبري | P16: محمود عبد العزيز | Q16: 1141398778 | S16: العنوان شبشير الحصة طريق طنطا المحلة الكبرى الكيلو ٩ على الطريق | T16: 1650 | U16: 10 | V16: 1 | W16: nan | X16: يناير 2025 | Y16: 16 | AD16: 4 | AI16: 2 | AP16: 4
A17: 16 | B17: 2025 | C17: 1 | D17: يناير | E17: 45685.924 | F17: سهيله | G17: سهيلة | H17: فيسبوك | I17: فيسبوك | J17: مندوب خاص | K17: مندوب خاص | L17: الغربية | M17: الغربية | N17: المحله الكبرى | P17: محمود علي عبدالله | Q17: 1110787627 | S17: المحله الكبرى سكه زفتي العمومي اعلي مطعم فلفله الدور الثاني | T17: 1890 | U17: 12 | V17: 1 | W17: nan | X17: يناير 2025 | Y17: 17 | AA17: 1 | AB17: 1 | AD17: 1 | AE17: 1 | AF17: 1 | AH17: 1 | AN17: 2 | AO17: 2 | AP17: 2
A18: 17 | B18: 2025 | C18: 1 | D18: يناير | E18: 45686.944 | F18: سهيله | G18: سهيلة | H18: فيسبوك | I18: فيسبوك | J18: مندوب خاص | K18: مندوب خاص | L18: الشرقية | M18: الشرقية | N18: الشرقيه | P18: ثروت الشرقاوي | Q18: 1006020654 | S18: فاقوس شرقيه خلف المعهد الديني | T18: 1305 | U18: 6 | V18: 1 | W18: nan | X18: يناير 2025 | Y18: 18 | AB18: 2 | AC18: 2 | AE18: 2
A19: 18 | B19: 2025 | C19: 1 | D19: يناير | E19: 45687.912 | F19: رانيا | G19: رانيا | H19: مكالمة / واتساب | I19: مكالمة / واتساب | J19: مندوب خاص | K19: مندوب خاص | L19: الدقهلية | M19: الدقهلية | N19: اجا | P19: محمود مصطفى | Q19: 1060505714 | S19: العنوان قريه نوسا البحر مركز اجا الدقهلية | T19: 3999 | U19: 18 | V19: 1 | W19: nan | X19: يناير 2025 | Y19: 19 | AA19: 4 | AB19: 4 | AH19: 2 | AI19: 2 | AL19: 2 | AO19: 2 | AP19: 2
A20: 19 | B20: 2025 | C20: 1 | D20: يناير | E20: 45668.753 | F20: رانيا | G20: رانيا | H20: مكالمة / واتساب | I20: مكالمة / واتساب | J20: هيستلم من المزرعه | K20: استلام من المزرعة | L20: الدقهلية | M20: الدقهلية | N20: المنصوره | P20: أنس | Q20: 1003054163 | S20: دكرنس المنصوره | T20: 5250 | U20: 70 | V20: 1 | W20: nan | X20: يناير 2025 | Y20: 20 | AL20: 70
A21: 20 | B21: 2025 | C21: 1 | D21: يناير | E21: 45670.998 | F21: سهيله | G21: سهيلة | H21: مكالمة / واتساب | I21: مكالمة / واتساب | J21: زودكس | K21: زودكس | L21: القاهرة | M21: القاهرة | N21: الزمالك | P21: احمد عطالله | Q21: 1030192080 | S21: ١٢ عزيز اباظه الزمالك الدور ٧ | T21: 1890 | U21: 10 | V21: 1 | W21: nan | X21: يناير 2025 | Y21: 21 | AA21: 1 | AB21: 1 | AD21: 1 | AH21: 1 | AN21: 2 | AO21: 2 | AP21: 2
A22: 21 | B22: 2025 | C22: 1 | D22: يناير | E22: 45674.791 | F22: سهيله | G22: سهيلة | H22: فيسبوك | I22: فيسبوك | J22: زودكس | K22: زودكس | L22: القاهرة | M22: القاهرة | N22: بشتيل | P22: حسام ابراهيم دسوقي ابراهيم | Q22: 1143177217 | S22: بشتيل اخر سهم الدائري بعد محطة مترو الدائري بشتيل اخر ب حوالي ك عند نادي استاد بشتيل الرياضي | T22: 3700 | U22: 18 | V22: 1 | W22: nan | X22: يناير 2025 | Y22: 22 | Z22: 12 | AH22: 2 | AI22: 2 | AJ22: 2
A23: 22 | B23: 2025 | C23: 1 | D23: يناير | E23: 45675.44 | F23: رانيا | G23: رانيا | H23: مكالمة / واتساب | I23: مكالمة / واتساب | J23: زودكس | K23: زودكس | L23: القاهرة | M23: القاهرة | N23: 6 اكتوبر | P23: بسيوني سليم | Q23: 1003824073 | R23: 1114530630 | S23: السادس من أكتوبر أبراج الأمريكية برج5 مقابل مسجد الشيخ الحصري تحت كنوز البن عبدالمعبود المركز الدولي للاعشاب والنباتات الطبية | T23: 2000 | U23: 20 | V23: 1 | W23: nan | X23: يناير 2025 | Y23: 23 | AL23: 20
A24: 23 | B24: 2025 | C24: 1 | D24: يناير | E24: 45681.903 | F24: آيه | G24: أية | H24: فيسبوك | I24: فيسبوك | J24: زودكس | K24: زودكس | L24: القاهرة | M24: القاهرة | N24: المهندسين | P24: محمد ابو المجد | Q24: 1128290011 | R24: 1021014259 | S24: 25ش سلامه الراضي ارض اللواء المهندسين | T24: 940 | U24: 4 | V24: 1 | W24: nan | X24: يناير 2025 | Y24: 24 | AB24: 4
A25: 24 | B25: 2025 | C25: 1 | D25: يناير | E25: 45682.998 | F25: رانيا | G25: رانيا | H25: مكالمة / واتساب | I25: مكالمة / واتساب | J25: استلم من المزرعه | K25: استلام من المزرعة | L25: الغربية | M25: الغربية | N25: طنطا | P25: محمد مصطفي | Q25: 1286976050 | S25: طنطا القرشي | T25: 600 | U25: 4 | V25: 1 | W25: nan | X25: يناير 2025 | Y25: 25 | AH25: 4
A26: 25 | B26: 2025 | C26: 1 | D26: يناير | E26: 45685.979 | F26: سهيله | G26: سهيلة | H26: فيسبوك | I26: فيسبوك | J26: زودكس | K26: زودكس | L26: الجيزة | M26: الجيزة | N26: الجيزه | P26: المهندسه نشوة العراقي | Q26: 1223710119 | S26: ٢٥ش العشرين محطه مدكور فيصل الجيزه الدور السابع شقه ٢٠ بجوار صيدليه الصحه | T26: 435 | U26: 2 | V26: 1 | W26: nan | X26: يناير 2025 | Y26: 26 | AB26: 1 | AE26: 1
A27: 26 | B27: 2025 | C27: 1 | D27: يناير | E27: 45686.075 | F27: سهيله | G27: سهيلة | H27: فيسبوك | I27: فيسبوك | J27: زودكس | K27: زودكس | L27: القاهرة | M27: القاهرة | N27: القاهرة | P27: مها نبيل حافظ | Q27: 1004958658 | R27: 222663108 | S27: مساكن شيراتون المطار مصر للتعمير المنطقة الاولى عمارة ٣٤ شقة ٥ | T27: 2397 | U27: 14 | V27: 1 | W27: nan | X27: يناير 2025 | Y27: 27 | AA27: 1 | AB27: 1 | AC27: 1 | AD27: 1 | AH27: 1 | AN27: 2 | AO27: 2 | AP27: 2 | AQ27: 2 | AU27: 1
A28: 27 | B28: 2025 | C28: 1 | D28: يناير | E28: 45686.7 | F28: آيه | G28: أية | H28: مكالمة / واتساب | I28: مكالمة / واتساب | J28: مندوب خاص | K28: مندوب خاص | L28: المنوفية | M28: المنوفية | N28: شبين | P28: رمضان | Q28: 1001320163 | S28: شبين الكوم أمام مركز شباب الحي القبلي | T28: 2730 | U28: 0 | V28: 1 | W28: دبوس 7ك | nan | X28: يناير 2025 | Y28: 28
A29: 28 | B29: 2025 | C29: 1 | D29: يناير | E29: 45686.717 | F29: آيه | G29: أية | H29: فيسبوك | I29: فيسبوك | J29: زودكس | K29: زودكس | L29: القاهرة | M29: القاهرة | N29: مدينتي | P29: نشوي | Q29: 1006757744 | S29: مدينتي م17 عماره28 شقه12 | T29: 1480 | U29: 7 | V29: 1 | W29: nan | X29: يناير 2025 | Y29: 29 | AA29: 2 | AC29: 2 | AF29: 2 | AH29: 1
A30: 29 | B30: 2025 | C30: 1 | D30: يناير | E30: 45686.722 | F30: آيه | G30: أية | H30: فيسبوك | I30: فيسبوك | J30: زودكس | K30: زودكس | L30: الجيزة | M30: الجيزة | N30: اكتوبر | P30: سيد حسن | Q30: 1004283599 | S30: اكتوبر الحي الثامن محور جمال عبد الناصر فاميلي لاند عماره6أ شقه7 | T30: 1890 | U30: 10 | V30: 1 | W30: nan | X30: يناير 2025 | Y30: 30 | AA30: 1 | AB30: 1 | AD30: 1 | AH30: 1 | AN30: 2 | AO30: 2 | AP30: 2
A31: 30 | B31: 2025 | C31: 1 | D31: يناير | E31: 45686.737 | F31: آيه | G31: أية | H31: فيسبوك | I31: فيسبوك | J31: زودكس | K31: زودكس | L31: الجيزة | M31: الجيزة | N31: فيصل | P31: سعد كمال | Q31: 1117997999 | S31: 1ش عيد مصطفى الدور 2 ش9 فيصل | T31: 1740 | U31: 8 | V31: 1 | W31: nan | X31: يناير 2025 | Y31: 31 | AB31: 8
A32: 31 | B32: 2025 | C32: 1 | D32: يناير | E32: 45686.889 | F32: آيه | G32: أية | H32: فيسبوك | I32: فيسبوك | J32: زودكس | K32: زودكس | L32: القاهرة | M32: القاهرة | N32: مدينه نصر | P32: احمد طلعت | Q32: 1223166369 | S32: 17ش د احمد ابراهيم من عباس العقاد أمام الحديقة الدولية ناصية مصر للطيران الدور7شقه72 | T32: 1305 | U32: 6 | V32: 1 | W32: nan | X32: يناير 2025 | Y32: 32 | AA32: 6
A33: 32 | B33: 2025 | C33: 1 | D33: يناير | E33: 45686.99 | F33: سهيله | G33: سهيلة | H33: فيسبوك | I33: فيسبوك | J33: مندوب خاص | K33: مندوب خاص | L33: المنوفية | M33: المنوفية | N33: تلا | P33: حسين محمد عبد المطلب | Q33: 1098281897 | S33: مركز تلا منوفيه | T33: 870 | U33: 4 | V33: 1 | W33: nan | X33: يناير 2025 | Y33: 33 | AB33: 2 | AE33: 2
A34: 33 | B34: 2025 | C34: 1 | D34: يناير | E34: 45687.704 | F34: آيه | G34: أية | H34: مكالمة / واتساب | I34: مكالمة / واتساب | J34: زودكس | K34: زودكس | L34: القاهرة | M34: القاهرة | N34: مدينه نصر | P34: الفت | Q34: 1551364331 | S34: زهراء مدينه نصر جاردينيا سيتي عماره 488 الدور الاول شقه12 | T34: 655 | U34: 3 | V34: 1 | W34: nan | X34: يناير 2025 | Y34: 34 | AA34: 3
A35: 34 | B35: 2025 | C35: 1 | D35: يناير | E35: 45687.973 | F35: سهيله | G35: سهيلة | H35: فيسبوك | I35: فيسبوك | J35: مندوب خاص | K35: مندوب خاص | L35: الشرقية | M35: الشرقية | N35: سماكين الغراب الحسينيه | P35: علي احمد عبدالعزيز | Q35: 1000866916 | S35: سماكين الغراب الحسينيه شرقيه | T35: 9830 | U35: 11 | V35: 1 | W35: فخدة 17 كيلو | nan | X35: يناير 2025 | Y35: 35 | AH35: 3 | AI35: 2 | AJ35: 3 | AK35: 3
A36: 35 | B36: 2025 | C36: 1 | D36: يناير | E36: 45688.468 | F36: رانيا | G36: رانيا | H36: مكالمة / واتساب | I36: مكالمة / واتساب | J36: مندوب خاص | K36: مندوب خاص | L36: الغربية | M36: الغربية | N36: زفتي | P36: نعمات السيد | Q36: 1099757807 | S36: زفتي شارع الجيش بجوار محل بيت الدواجن بجوار فرن طه | T36: 655 | U36: 4 | V36: 1 | W36: nan | X36: يناير 2025 | Y36: 36 | Z36: 2 | AK36: 2
A37: 36 | B37: 2025 | C37: 1 | D37: يناير | E37: 45688.698 | F37: رانيا | G37: رانيا | H37: مكالمة / واتساب | I37: مكالمة / واتساب | J37: مندوب خاص | K37: مندوب خاص | L37: الغربية | M37: الغربية | N37: زفتي | P37: محمود الوكيل | Q37: 1014590505 | S37: زفتي بعد مدرسه الصنايع شار الجيش | T37: 870 | U37: 4 | V37: 1 | W37: nan | X37: يناير 2025 | Y37: 37 | AA37: 4
A38: 37 | B38: 2025 | C38: 1 | D38: يناير | E38: 45688.772 | F38: سهيله | G38: سهيلة | H38: فيسبوك | I38: فيسبوك | J38: مندوب خاص | K38: مندوب خاص | L38: القليوبية | M38: القليوبية | N38: بنها المنشيه | P38: نعمه الطوخي | Q38: 1283640004 | S38: القليوبية بنها المنشية شارع الروضة فوق مخبز الإخوة | T38: 2960 | U38: 14 | V38: 1 | W38: nan | X38: يناير 2025 | Y38: 38 | AA38: 6 | AB38: 6 | AN38: 2
A39: 38 | B39: 2025 | C39: 1 | D39: يناير | E39: 45688.784 | F39: آيه | G39: أية | H39: مكالمة / واتساب | I39: مكالمة / واتساب | J39: زودكس | K39: زودكس | L39: الجيزة | M39: الجيزة | N39: الهرم | P39: اسماء | Q39: 1111822351 | R39: 1007361256 | S39: 13ش عوض داود من الرضا ترسا الكوم الاخضر الهرم | T39: 1250 | U39: 10 | V39: 1 | W39: nan | X39: يناير 2025 | Y39: 39 | AH39: 1 | AI39: 2 | AJ39: 1 | AK39: 2 | AN39: 2 | AO39: 2
A40: 39 | B40: 2025 | C40: 1 | D40: يناير | E40: 45688.996 | F40: رانيا | G40: رانيا | H40: مكالمة / واتساب | I40: مكالمة / واتساب | J40: مندوب خاص | K40: مندوب خاص | L40: الشرقية | M40: الشرقية | N40: الزقازيق | P40: مدام أمل | Q40: 1227009388 | S40: الزقازيق شارع فاروق برج ابو السعود 6 | T40: 1510 | U40: 10 | V40: 1 | W40: nan | X40: يناير 2025 | Y40: 40 | AA40: 2 | AK40: 8
...
